Namespace(N_min=2000, dir='/project2/depablo/walt/michrom/project/chr_05/chr_05_02', down_sampling=12, its=5, jobs=20, mode='contact_diffusion', odir='/project2/depablo/erschultz/michrom/project/chr_05/chr_05_02_copy2/contact_diffusion', sparse_format=False, update_mode='eig')
Loaded xyz with shape (1007, 3620, 3)
xyz load time: 109.323 s
found 28 total CPUs, 20 available CPUs, using 20
multiprocessing.pool.RemoteTraceback: 
"""
Traceback (most recent call last):
  File "/home/erschultz/miniconda3/envs/python3.8_pytorch1.8.1_cuda10.2_2/lib/python3.8/multiprocessing/pool.py", line 125, in worker
    result = (True, func(*args, **kwds))
  File "/home/erschultz/miniconda3/envs/python3.8_pytorch1.8.1_cuda10.2_2/lib/python3.8/multiprocessing/pool.py", line 51, in starmapstar
    return list(itertools.starmap(args[0], args[1]))
  File "/home/erschultz/sequences_to_contact_maps/utils/load_utils.py", line 261, in save_sc_contacts_xyz
    np.save(ofile, contact_map)
  File "<__array_function__ internals>", line 5, in save
  File "/home/erschultz/miniconda3/envs/python3.8_pytorch1.8.1_cuda10.2_2/lib/python3.8/site-packages/numpy/lib/npyio.py", line 529, in save
    format.write_array(fid, arr, allow_pickle=allow_pickle,
  File "/home/erschultz/miniconda3/envs/python3.8_pytorch1.8.1_cuda10.2_2/lib/python3.8/site-packages/numpy/lib/format.py", line 687, in write_array
    array.tofile(fp)
OSError: 6554010 requested and 0 written
"""

The above exception was the direct cause of the following exception:

Traceback (most recent call last):
  File "diffusion_analysis.py", line 545, in <module>
    main()
  File "diffusion_analysis.py", line 539, in main
    contact_diffusion()
  File "diffusion_analysis.py", line 390, in contact_diffusion
    xyz = load_helper(args, True)
  File "diffusion_analysis.py", line 303, in load_helper
    save_sc_contacts(xyz, args.sc_contacts_dir, args.jobs, sparsify = True)
  File "/home/erschultz/sequences_to_contact_maps/utils/load_utils.py", line 237, in save_sc_contacts
    p.starmap(save_sc_contacts_xyz, mapping)
  File "/home/erschultz/miniconda3/envs/python3.8_pytorch1.8.1_cuda10.2_2/lib/python3.8/multiprocessing/pool.py", line 372, in starmap
    return self._map_async(func, iterable, starmapstar, chunksize).get()
  File "/home/erschultz/miniconda3/envs/python3.8_pytorch1.8.1_cuda10.2_2/lib/python3.8/multiprocessing/pool.py", line 771, in get
    raise self._value
OSError: 6554010 requested and 0 written
