/tmp/slurmd/job14383981/slurm_script: line 21: activate: No such file or directory
Namespace(GNN_mode=False, batch_size=1, input_folder='/project2/depablo/erschultz/dataset_08_29_21', k=2, min_sample=0, n=1024, num_workers=20, output_folder='/project2/depablo/erschultz/dataset_08_29_21', overwrite=True, percentiles=None, sample_size=200, seed=42, shuffle=True, split=[0.8, 0.1, 0.1], use_batch_for_diag=False, use_x2xx=False)
Input folder:  /project2/depablo/erschultz/dataset_08_29_21
Output folder:  /project2/depablo/erschultz/dataset_08_29_21
multiprocessing.pool.RemoteTraceback: 
"""
Traceback (most recent call last):
  File "/home/erschultz/miniconda3/envs/python3.8_pytorch1.8.1_cuda10.2/lib/python3.8/multiprocessing/pool.py", line 125, in worker
    result = (True, func(*args, **kwds))
  File "/home/erschultz/miniconda3/envs/python3.8_pytorch1.8.1_cuda10.2/lib/python3.8/multiprocessing/pool.py", line 51, in starmapstar
    return list(itertools.starmap(args[0], args[1]))
TypeError: process_sample_save() missing 1 required positional argument: 'use_x2xx'
"""

The above exception was the direct cause of the following exception:

Traceback (most recent call last):
  File "preprocess_data.py", line 227, in <module>
    main()
  File "preprocess_data.py", line 198, in main
    p.starmap(process_sample_save, mapping)
  File "/home/erschultz/miniconda3/envs/python3.8_pytorch1.8.1_cuda10.2/lib/python3.8/multiprocessing/pool.py", line 372, in starmap
    return self._map_async(func, iterable, starmapstar, chunksize).get()
  File "/home/erschultz/miniconda3/envs/python3.8_pytorch1.8.1_cuda10.2/lib/python3.8/multiprocessing/pool.py", line 771, in get
    raise self._value
TypeError: process_sample_save() missing 1 required positional argument: 'use_x2xx'
